<?xml version="1.0"?>
<robot xmlns:xacro="http://www.ros.org/wiki/xacro">
  <xacro:macro name="elevator" params="">
    <link name="elevator_platform">
      <visual>
        <geometry>
          <box size="0.8 0.8 0.1"/>
        </geometry>
        <material name="red"/>
      </visual>
      <collision>
        <geometry>
          <box size="0.8 0.8 0.1"/>
        </geometry>
      </collision>
      <inertial>
        <mass value="1.0"/> <!-- Adjust mass as needed -->
        <origin xyz="0 0 0" rpy="0 0 0"/> <!-- Center of mass -->
        <inertia ixx="0.0053" ixy="0.0" ixz="0.0" iyy="0.0053" iyz="0.0" izz="0.1067"/> <!-- Inertia values -->
      </inertial>
    </link>

    <joint name="elevator_joint" type="prismatic">
        <parent link="base_link"/>
        <child link="elevator_platform"/>
        <origin xyz="0 0 0.1" rpy="0 0 0"/>
        <axis xyz="0 0 1"/>
        <limit lower="0.0" upper="1.0" effort="50.0" velocity="0.5"/>
        <dynamics damping="0.5" friction="0.1"/>
        <hardwareInterface>Position</hardwareInterface> <!-- Add this if missing -->
    </joint>

  </xacro:macro>
</robot>
