<?xml version="1.0"?>
<robot xmlns:xacro="http://www.ros.org/wiki/xacro" name="my_bot">

  <!-- Materials -->
  <material name="gray">
    <color rgba="0.5 0.5 0.5 1"/>
  </material>
  <material name="blue">
    <color rgba="0.0 0.0 1.0 1"/>
  </material>
  <material name="red">
    <color rgba="1.0 0.0 0.0 1"/>
  </material>

  <!-- Base Link -->
  <link name="base_link">
    <visual>
      <geometry>
        <box size="1 1 0.1"/>
      </geometry>
      <material name="gray"/>
    </visual>
    <collision>
      <geometry>
        <box size="1 1 0.1"/>
      </geometry>
    </collision>
    <inertial>
      <mass value="1.0"/>
      <origin xyz="0 0 0" rpy="0 0 0"/>
      <inertia ixx="0.0053" ixy="0.0" ixz="0.0" iyy="0.0053" iyz="0.0" izz="0.1067"/>
    </inertial>
  </link>

  <!-- Frame -->
  <link name="frame_1">
    <visual>
      <geometry>
        <cylinder length="2" radius="0.05"/>
      </geometry>
      <material name="blue"/>
    </visual>
    <collision>
      <geometry>
        <cylinder length="2" radius="0.05"/>
      </geometry>
    </collision>
    <inertial>
      <mass value="0.5"/>
      <origin xyz="0 0 0" rpy="0 0 0"/>
      <inertia ixx="0.0042" ixy="0.0" ixz="0.0" iyy="0.0042" iyz="0.0" izz="0.0417"/>
    </inertial>
  </link>

  <link name="frame_2">
    <visual>
      <geometry>
        <cylinder length="2" radius="0.05"/>
      </geometry>
      <material name="blue"/>
    </visual>
    <collision>
      <geometry>
        <cylinder length="2" radius="0.05"/>
      </geometry>
    </collision>
    <inertial>
      <mass value="0.5"/>
      <origin xyz="0 0 0" rpy="0 0 0"/>
      <inertia ixx="0.0042" ixy="0.0" ixz="0.0" iyy="0.0042" iyz="0.0" izz="0.0417"/>
    </inertial>
  </link>

  <joint name="frame_1_joint" type="fixed">
    <parent link="base_link"/>
    <child link="frame_1"/>
    <origin xyz="0.4 0.4 1" rpy="0 0 0"/>
  </joint>

  <joint name="frame_2_joint" type="fixed">
    <parent link="base_link"/>
    <child link="frame_2"/>
    <origin xyz="0.4 -0.4 1" rpy="0 0 0"/>
  </joint>

  <!-- Elevator -->
  <link name="elevator_platform">
    <visual>
      <geometry>
        <box size="0.8 0.8 0.1"/>
      </geometry>
      <material name="red"/>
    </visual>
    <collision>
      <geometry>
        <box size="0.8 0.8 0.1"/>
      </geometry>
    </collision>
    <inertial>
      <mass value="1.0"/>
      <origin xyz="0 0 0" rpy="0 0 0"/>
      <inertia ixx="0.0053" ixy="0.0" ixz="0.0" iyy="0.0053" iyz="0.0" izz="0.1067"/>
    </inertial>
  </link>

  <joint name="elevator_joint" type="prismatic">
    <parent link="base_link"/>
    <child link="elevator_platform"/>
    <origin xyz="0 0 0.1" rpy="0 0 0"/>
    <axis xyz="0 0 1"/>
    <limit lower="0.0" upper="1.0" effort="50.0" velocity="0.5"/>
    <dynamics damping="0.5" friction="0.1"/>
    <hardwareInterface>Position</hardwareInterface>
  </joint>


  <!-- Transmission for gazebo 
  <transmission name="elevator_transmission">
    <type>transmission_interface/SimpleTransmission</type>
    <joint name="elevator_joint">
      <hardwareInterface>hardware_interface/PositionJointInterface</hardwareInterface>
    </joint>
    <actuator name="elevator_motor">
      <hardwareInterface>hardware_interface/PositionJointInterface</hardwareInterface>
      <mechanicalReduction>1.0</mechanicalReduction>
    </actuator>
  </transmission> -->

  <!-- ROS 2 Control -->
  <ros2_control name="elevator_hw" type="system">
    <hardware>
      <plugin>gazebo_ros2_control/GazeboSystem</plugin> 
    </hardware>
    <joint name="elevator_joint">
      <command_interface name="position"/>
      <state_interface name="position"/>
    </joint>
  </ros2_control>

 <!-- Gazebo Plugins -->
  <gazebo>
    <plugin name="gazebo_ros2_control" filename="libgazebo_ros2_control.so">
        <parameters>$(find my_bot)/config/elevator_controllers.yaml</parameters>
    </plugin>	
  </gazebo>

</robot>
